[2025-09-11T01:09:51.008+0000] {taskinstance.py:1956} INFO - Dependencies all met for dep_context=non-requeueable deps ti=<TaskInstance: aviationstack_kafka_dag.run_bronze_load scheduled__2025-09-10T08:00:00+00:00 [queued]>
[2025-09-11T01:09:51.011+0000] {taskinstance.py:1956} INFO - Dependencies all met for dep_context=requeueable deps ti=<TaskInstance: aviationstack_kafka_dag.run_bronze_load scheduled__2025-09-10T08:00:00+00:00 [queued]>
[2025-09-11T01:09:51.011+0000] {taskinstance.py:2170} INFO - Starting attempt 1 of 1
[2025-09-11T01:09:51.014+0000] {taskinstance.py:2191} INFO - Executing <Task(PythonOperator): run_bronze_load> on 2025-09-10 08:00:00+00:00
[2025-09-11T01:09:51.016+0000] {standard_task_runner.py:60} INFO - Started process 187 to run task
[2025-09-11T01:09:51.017+0000] {standard_task_runner.py:87} INFO - Running: ['airflow', 'tasks', 'run', 'aviationstack_kafka_dag', 'run_bronze_load', 'scheduled__2025-09-10T08:00:00+00:00', '--job-id', '53', '--raw', '--subdir', 'DAGS_FOLDER/aviationstack_dag.py', '--cfg-path', '/tmp/tmpleftiofr']
[2025-09-11T01:09:51.018+0000] {standard_task_runner.py:88} INFO - Job 53: Subtask run_bronze_load
[2025-09-11T01:09:51.024+0000] {logging_mixin.py:188} WARNING - /home/airflow/.local/lib/python3.11/site-packages/airflow/settings.py:194 DeprecationWarning: The sql_alchemy_conn option in [core] has been moved to the sql_alchemy_conn option in [database] - the old setting has been used, but please update your config.
[2025-09-11T01:09:51.036+0000] {task_command.py:423} INFO - Running <TaskInstance: aviationstack_kafka_dag.run_bronze_load scheduled__2025-09-10T08:00:00+00:00 [running]> on host 23b62a8a4bcf
[2025-09-11T01:09:51.060+0000] {taskinstance.py:2480} INFO - Exporting env vars: AIRFLOW_CTX_DAG_OWNER='airflow' AIRFLOW_CTX_DAG_ID='aviationstack_kafka_dag' AIRFLOW_CTX_TASK_ID='run_bronze_load' AIRFLOW_CTX_EXECUTION_DATE='2025-09-10T08:00:00+00:00' AIRFLOW_CTX_TRY_NUMBER='1' AIRFLOW_CTX_DAG_RUN_ID='scheduled__2025-09-10T08:00:00+00:00'
[2025-09-11T01:09:51.070+0000] {base.py:83} INFO - Using connection ID 'postgres_default' for task execution.
[2025-09-11T01:09:51.072+0000] {logging_mixin.py:188} INFO - [INFO] Reading data from JSON file
[2025-09-11T01:09:51.072+0000] {taskinstance.py:2698} ERROR - Task failed with exception
Traceback (most recent call last):
  File "/home/airflow/.local/lib/python3.11/site-packages/airflow/models/taskinstance.py", line 433, in _execute_task
    result = execute_callable(context=context, **execute_callable_kwargs)
             ^^^^^^^^^^^^^^^^^^^^^^^^^^^^^^^^^^^^^^^^^^^^^^^^^^^^^^^^^^^^
  File "/home/airflow/.local/lib/python3.11/site-packages/airflow/operators/python.py", line 199, in execute
    return_value = self.execute_callable()
                   ^^^^^^^^^^^^^^^^^^^^^^^
  File "/home/airflow/.local/lib/python3.11/site-packages/airflow/operators/python.py", line 216, in execute_callable
    return self.python_callable(*self.op_args, **self.op_kwargs)
           ^^^^^^^^^^^^^^^^^^^^^^^^^^^^^^^^^^^^^^^^^^^^^^^^^^^^^
  File "/opt/airflow/etl/bronze/avstack/bronze_load.py", line 33, in insert_into_bronze_ddl
    with open(filepath, "r") as f:
         ^^^^^^^^^^^^^^^^^^^
TypeError: expected str, bytes or os.PathLike object, not NoneType
[2025-09-11T01:09:51.075+0000] {taskinstance.py:1138} INFO - Marking task as FAILED. dag_id=aviationstack_kafka_dag, task_id=run_bronze_load, execution_date=20250910T080000, start_date=20250911T010951, end_date=20250911T010951
[2025-09-11T01:09:51.079+0000] {standard_task_runner.py:107} ERROR - Failed to execute job 53 for task run_bronze_load (expected str, bytes or os.PathLike object, not NoneType; 187)
[2025-09-11T01:09:51.115+0000] {local_task_job_runner.py:234} INFO - Task exited with return code 1
[2025-09-11T01:09:51.124+0000] {taskinstance.py:3280} INFO - 0 downstream tasks scheduled from follow-on schedule check
[2025-09-11T03:28:58.734+0000] {taskinstance.py:1956} INFO - Dependencies all met for dep_context=non-requeueable deps ti=<TaskInstance: aviationstack_kafka_dag.run_bronze_load scheduled__2025-09-10T08:00:00+00:00 [queued]>
[2025-09-11T03:28:58.737+0000] {taskinstance.py:1956} INFO - Dependencies all met for dep_context=requeueable deps ti=<TaskInstance: aviationstack_kafka_dag.run_bronze_load scheduled__2025-09-10T08:00:00+00:00 [queued]>
[2025-09-11T03:28:58.737+0000] {taskinstance.py:2170} INFO - Starting attempt 1 of 1
[2025-09-11T03:28:58.741+0000] {taskinstance.py:2191} INFO - Executing <Task(PythonOperator): run_bronze_load> on 2025-09-10 08:00:00+00:00
[2025-09-11T03:28:58.743+0000] {standard_task_runner.py:60} INFO - Started process 256 to run task
[2025-09-11T03:28:58.744+0000] {standard_task_runner.py:87} INFO - Running: ['airflow', 'tasks', 'run', 'aviationstack_kafka_dag', 'run_bronze_load', 'scheduled__2025-09-10T08:00:00+00:00', '--job-id', '4', '--raw', '--subdir', 'DAGS_FOLDER/aviationstack_dag.py', '--cfg-path', '/tmp/tmp5fqhibx4']
[2025-09-11T03:28:58.745+0000] {standard_task_runner.py:88} INFO - Job 4: Subtask run_bronze_load
[2025-09-11T03:28:58.752+0000] {logging_mixin.py:188} WARNING - /home/airflow/.local/lib/python3.11/site-packages/airflow/settings.py:194 DeprecationWarning: The sql_alchemy_conn option in [core] has been moved to the sql_alchemy_conn option in [database] - the old setting has been used, but please update your config.
[2025-09-11T03:28:58.766+0000] {task_command.py:423} INFO - Running <TaskInstance: aviationstack_kafka_dag.run_bronze_load scheduled__2025-09-10T08:00:00+00:00 [running]> on host 81f5a06342ec
[2025-09-11T03:28:58.796+0000] {taskinstance.py:2480} INFO - Exporting env vars: AIRFLOW_CTX_DAG_OWNER='airflow' AIRFLOW_CTX_DAG_ID='aviationstack_kafka_dag' AIRFLOW_CTX_TASK_ID='run_bronze_load' AIRFLOW_CTX_EXECUTION_DATE='2025-09-10T08:00:00+00:00' AIRFLOW_CTX_TRY_NUMBER='1' AIRFLOW_CTX_DAG_RUN_ID='scheduled__2025-09-10T08:00:00+00:00'
[2025-09-11T03:28:58.807+0000] {base.py:83} INFO - Using connection ID 'postgres_default' for task execution.
[2025-09-11T03:28:58.810+0000] {taskinstance.py:2698} ERROR - Task failed with exception
Traceback (most recent call last):
  File "/home/airflow/.local/lib/python3.11/site-packages/airflow/models/taskinstance.py", line 433, in _execute_task
    result = execute_callable(context=context, **execute_callable_kwargs)
             ^^^^^^^^^^^^^^^^^^^^^^^^^^^^^^^^^^^^^^^^^^^^^^^^^^^^^^^^^^^^
  File "/home/airflow/.local/lib/python3.11/site-packages/airflow/operators/python.py", line 199, in execute
    return_value = self.execute_callable()
                   ^^^^^^^^^^^^^^^^^^^^^^^
  File "/home/airflow/.local/lib/python3.11/site-packages/airflow/operators/python.py", line 216, in execute_callable
    return self.python_callable(*self.op_args, **self.op_kwargs)
           ^^^^^^^^^^^^^^^^^^^^^^^^^^^^^^^^^^^^^^^^^^^^^^^^^^^^^
  File "/opt/airflow/etl/bronze/avstack/bronze_load.py", line 29, in insert_into_bronze_ddl
    conn = hook.get_conn()
           ^^^^^^^^^^^^^^^
  File "/home/airflow/.local/lib/python3.11/site-packages/airflow/providers/postgres/hooks/postgres.py", line 158, in get_conn
    self.conn = psycopg2.connect(**conn_args)
                ^^^^^^^^^^^^^^^^^^^^^^^^^^^^^
  File "/home/airflow/.local/lib/python3.11/site-packages/psycopg2/__init__.py", line 122, in connect
    conn = _connect(dsn, connection_factory=connection_factory, **kwasync)
           ^^^^^^^^^^^^^^^^^^^^^^^^^^^^^^^^^^^^^^^^^^^^^^^^^^^^^^^^^^^^^^^
psycopg2.OperationalError: connection to server at "postgres" (172.18.0.3), port 5432 failed: FATAL:  ***word authentication failed for user "postgres"

[2025-09-11T03:28:58.814+0000] {taskinstance.py:1138} INFO - Marking task as FAILED. dag_id=aviationstack_kafka_dag, task_id=run_bronze_load, execution_date=20250910T080000, start_date=20250911T032858, end_date=20250911T032858
[2025-09-11T03:28:58.817+0000] {standard_task_runner.py:107} ERROR - Failed to execute job 4 for task run_bronze_load (connection to server at "postgres" (172.18.0.3), port 5432 failed: FATAL:  ***word authentication failed for user "postgres"
; 256)
[2025-09-11T03:28:58.844+0000] {local_task_job_runner.py:234} INFO - Task exited with return code 1
[2025-09-11T03:28:58.853+0000] {taskinstance.py:3280} INFO - 0 downstream tasks scheduled from follow-on schedule check
