[2025-09-10T08:05:37.165+0000] {taskinstance.py:1956} INFO - Dependencies all met for dep_context=non-requeueable deps ti=<TaskInstance: aviationstack_kafka_dag.run_bronze_load manual__2025-09-10T08:05:31.305716+00:00 [queued]>
[2025-09-10T08:05:37.167+0000] {taskinstance.py:1956} INFO - Dependencies all met for dep_context=requeueable deps ti=<TaskInstance: aviationstack_kafka_dag.run_bronze_load manual__2025-09-10T08:05:31.305716+00:00 [queued]>
[2025-09-10T08:05:37.167+0000] {taskinstance.py:2170} INFO - Starting attempt 1 of 1
[2025-09-10T08:05:37.171+0000] {taskinstance.py:2191} INFO - Executing <Task(PythonOperator): run_bronze_load> on 2025-09-10 08:05:31.305716+00:00
[2025-09-10T08:05:37.173+0000] {standard_task_runner.py:60} INFO - Started process 277 to run task
[2025-09-10T08:05:37.174+0000] {standard_task_runner.py:87} INFO - Running: ['airflow', 'tasks', 'run', 'aviationstack_kafka_dag', 'run_bronze_load', 'manual__2025-09-10T08:05:31.305716+00:00', '--job-id', '17', '--raw', '--subdir', 'DAGS_FOLDER/aviationstack_dag.py', '--cfg-path', '/tmp/tmp30cz3ceb']
[2025-09-10T08:05:37.175+0000] {standard_task_runner.py:88} INFO - Job 17: Subtask run_bronze_load
[2025-09-10T08:05:37.181+0000] {logging_mixin.py:188} WARNING - /home/airflow/.local/lib/python3.11/site-packages/airflow/settings.py:194 DeprecationWarning: The sql_alchemy_conn option in [core] has been moved to the sql_alchemy_conn option in [database] - the old setting has been used, but please update your config.
[2025-09-10T08:05:37.193+0000] {task_command.py:423} INFO - Running <TaskInstance: aviationstack_kafka_dag.run_bronze_load manual__2025-09-10T08:05:31.305716+00:00 [running]> on host 22c3e565ec20
[2025-09-10T08:05:37.218+0000] {taskinstance.py:2480} INFO - Exporting env vars: AIRFLOW_CTX_DAG_OWNER='airflow' AIRFLOW_CTX_DAG_ID='aviationstack_kafka_dag' AIRFLOW_CTX_TASK_ID='run_bronze_load' AIRFLOW_CTX_EXECUTION_DATE='2025-09-10T08:05:31.305716+00:00' AIRFLOW_CTX_TRY_NUMBER='1' AIRFLOW_CTX_DAG_RUN_ID='manual__2025-09-10T08:05:31.305716+00:00'
[2025-09-10T08:05:37.228+0000] {base.py:83} INFO - Using connection ID 'postgres_default' for task execution.
[2025-09-10T08:05:37.230+0000] {taskinstance.py:2698} ERROR - Task failed with exception
Traceback (most recent call last):
  File "/home/airflow/.local/lib/python3.11/site-packages/airflow/models/taskinstance.py", line 433, in _execute_task
    result = execute_callable(context=context, **execute_callable_kwargs)
             ^^^^^^^^^^^^^^^^^^^^^^^^^^^^^^^^^^^^^^^^^^^^^^^^^^^^^^^^^^^^
  File "/home/airflow/.local/lib/python3.11/site-packages/airflow/operators/python.py", line 199, in execute
    return_value = self.execute_callable()
                   ^^^^^^^^^^^^^^^^^^^^^^^
  File "/home/airflow/.local/lib/python3.11/site-packages/airflow/operators/python.py", line 216, in execute_callable
    return self.python_callable(*self.op_args, **self.op_kwargs)
           ^^^^^^^^^^^^^^^^^^^^^^^^^^^^^^^^^^^^^^^^^^^^^^^^^^^^^
  File "/opt/airflow/etl/bronze/avstack/bronze_load.py", line 29, in insert_into_bronze_ddl
    conn = hook.get_conn()
           ^^^^^^^^^^^^^^^
  File "/home/airflow/.local/lib/python3.11/site-packages/airflow/providers/postgres/hooks/postgres.py", line 158, in get_conn
    self.conn = psycopg2.connect(**conn_args)
                ^^^^^^^^^^^^^^^^^^^^^^^^^^^^^
  File "/home/airflow/.local/lib/python3.11/site-packages/psycopg2/__init__.py", line 122, in connect
    conn = _connect(dsn, connection_factory=connection_factory, **kwasync)
           ^^^^^^^^^^^^^^^^^^^^^^^^^^^^^^^^^^^^^^^^^^^^^^^^^^^^^^^^^^^^^^^
psycopg2.OperationalError: connection to server at "postgres" (172.18.0.3), port 5432 failed: FATAL:  ***word authentication failed for user "postgres"

[2025-09-10T08:05:37.234+0000] {taskinstance.py:1138} INFO - Marking task as FAILED. dag_id=aviationstack_kafka_dag, task_id=run_bronze_load, execution_date=20250910T080531, start_date=20250910T080537, end_date=20250910T080537
[2025-09-10T08:05:37.237+0000] {standard_task_runner.py:107} ERROR - Failed to execute job 17 for task run_bronze_load (connection to server at "postgres" (172.18.0.3), port 5432 failed: FATAL:  ***word authentication failed for user "postgres"
; 277)
[2025-09-10T08:05:37.273+0000] {local_task_job_runner.py:234} INFO - Task exited with return code 1
[2025-09-10T08:05:37.281+0000] {taskinstance.py:3280} INFO - 0 downstream tasks scheduled from follow-on schedule check
