[2025-09-10T08:53:46.148+0000] {taskinstance.py:1956} INFO - Dependencies all met for dep_context=non-requeueable deps ti=<TaskInstance: aviationstack_kafka_dag.run_kafka_consumer manual__2025-09-10T08:53:38.167127+00:00 [queued]>
[2025-09-10T08:53:46.151+0000] {taskinstance.py:1956} INFO - Dependencies all met for dep_context=requeueable deps ti=<TaskInstance: aviationstack_kafka_dag.run_kafka_consumer manual__2025-09-10T08:53:38.167127+00:00 [queued]>
[2025-09-10T08:53:46.151+0000] {taskinstance.py:2170} INFO - Starting attempt 1 of 1
[2025-09-10T08:53:46.156+0000] {taskinstance.py:2191} INFO - Executing <Task(PythonOperator): run_kafka_consumer> on 2025-09-10 08:53:38.167127+00:00
[2025-09-10T08:53:46.158+0000] {standard_task_runner.py:60} INFO - Started process 194 to run task
[2025-09-10T08:53:46.160+0000] {standard_task_runner.py:87} INFO - Running: ['airflow', 'tasks', 'run', 'aviationstack_kafka_dag', 'run_kafka_consumer', 'manual__2025-09-10T08:53:38.167127+00:00', '--job-id', '36', '--raw', '--subdir', 'DAGS_FOLDER/aviationstack_dag.py', '--cfg-path', '/tmp/tmpjghf0lhu']
[2025-09-10T08:53:46.161+0000] {standard_task_runner.py:88} INFO - Job 36: Subtask run_kafka_consumer
[2025-09-10T08:53:46.168+0000] {logging_mixin.py:188} WARNING - /home/airflow/.local/lib/python3.11/site-packages/airflow/settings.py:194 DeprecationWarning: The sql_alchemy_conn option in [core] has been moved to the sql_alchemy_conn option in [database] - the old setting has been used, but please update your config.
[2025-09-10T08:53:46.183+0000] {task_command.py:423} INFO - Running <TaskInstance: aviationstack_kafka_dag.run_kafka_consumer manual__2025-09-10T08:53:38.167127+00:00 [running]> on host 3cccbea8256f
[2025-09-10T08:53:46.213+0000] {taskinstance.py:2480} INFO - Exporting env vars: AIRFLOW_CTX_DAG_OWNER='airflow' AIRFLOW_CTX_DAG_ID='aviationstack_kafka_dag' AIRFLOW_CTX_TASK_ID='run_kafka_consumer' AIRFLOW_CTX_EXECUTION_DATE='2025-09-10T08:53:38.167127+00:00' AIRFLOW_CTX_TRY_NUMBER='1' AIRFLOW_CTX_DAG_RUN_ID='manual__2025-09-10T08:53:38.167127+00:00'
[2025-09-10T08:53:46.214+0000] {logging_mixin.py:188} INFO - Starting consumer...
[2025-09-10T08:53:46.215+0000] {conn.py:396} INFO - <BrokerConnection client_id=kafka-python-2.2.15, node_id=1 host=kafka:9092 <connecting> [IPv4 ('172.18.0.4', 9092)]>: connecting to kafka:9092 [('172.18.0.4', 9092) IPv4]
[2025-09-10T08:53:46.216+0000] {conn.py:457} INFO - <BrokerConnection client_id=kafka-python-2.2.15, node_id=1 host=kafka:9092 <connected> [IPv4 ('172.18.0.4', 9092)]>: Connection complete.
[2025-09-10T08:53:46.216+0000] {conn.py:945} INFO - <BrokerConnection client_id=kafka-python-2.2.15, node_id=bootstrap-0 host=kafka:9092 <connected> [IPv4 ('172.18.0.4', 9092)]>: Closing connection. 
[2025-09-10T08:53:46.322+0000] {cluster.py:401} INFO - Coordinator for group/aviation_flight_data_test_group_01 is ('coordinator-1', 'kafka', 9092, None)
[2025-09-10T08:53:46.322+0000] {base.py:788} INFO - Discovered coordinator coordinator-1 for group aviation_flight_data_test_group_01
[2025-09-10T08:53:46.322+0000] {base.py:848} INFO - Starting new heartbeat thread
[2025-09-10T08:53:46.323+0000] {consumer.py:365} INFO - Revoking previously assigned partitions () for group aviation_flight_data_test_group_01
[2025-09-10T08:53:46.323+0000] {base.py:419} INFO - Failed to join group aviation_flight_data_test_group_01: NodeNotReadyError: coordinator-1
[2025-09-10T08:53:46.324+0000] {conn.py:396} INFO - <BrokerConnection client_id=kafka-python-2.2.15, node_id=coordinator-1 host=kafka:9092 <connecting> [IPv4 ('172.18.0.4', 9092)]>: connecting to kafka:9092 [('172.18.0.4', 9092) IPv4]
[2025-09-10T08:53:46.324+0000] {conn.py:457} INFO - <BrokerConnection client_id=kafka-python-2.2.15, node_id=coordinator-1 host=kafka:9092 <connected> [IPv4 ('172.18.0.4', 9092)]>: Connection complete.
[2025-09-10T08:53:46.425+0000] {base.py:532} INFO - (Re-)joining group aviation_flight_data_test_group_01
[2025-09-10T08:53:46.430+0000] {base.py:637} INFO - Received member id kafka-python-2.2.15-c04b4a92-ecb3-4757-9cb3-a4b25cdbe76d for group aviation_flight_data_test_group_01; will retry join-group
[2025-09-10T08:53:46.430+0000] {base.py:419} INFO - Failed to join group aviation_flight_data_test_group_01: [Error 79] MemberIdRequiredError
[2025-09-10T08:53:46.431+0000] {base.py:532} INFO - (Re-)joining group aviation_flight_data_test_group_01
[2025-09-10T08:53:49.438+0000] {base.py:594} INFO - Successfully joined group aviation_flight_data_test_group_01 <Generation 1 (member_id: kafka-python-2.2.15-c04b4a92-ecb3-4757-9cb3-a4b25cdbe76d, protocol: range)>
[2025-09-10T08:53:49.439+0000] {base.py:596} INFO - Elected group leader -- performing partition assignments using range
[2025-09-10T08:53:49.444+0000] {subscription_state.py:254} INFO - Updated partition assignment: [('aviation_flight_data', 0)]
[2025-09-10T08:53:49.445+0000] {consumer.py:249} INFO - Setting newly assigned partitions (('aviation_flight_data', 0),) for group aviation_flight_data_test_group_01
[2025-09-10T08:53:49.447+0000] {fetcher.py:418} INFO - Resetting offset for partition ('aviation_flight_data', 0) to offset 0.
[2025-09-10T08:53:49.491+0000] {kafka_consumer.py:54} INFO - Kafka payload: {'error': {'code': 'invalid_access_key', 'message': 'You have not supplied a valid API Access Key.'}}
[2025-09-10T08:53:49.492+0000] {taskinstance.py:2698} ERROR - Task failed with exception
Traceback (most recent call last):
  File "/home/airflow/.local/lib/python3.11/site-packages/airflow/models/taskinstance.py", line 433, in _execute_task
    result = execute_callable(context=context, **execute_callable_kwargs)
             ^^^^^^^^^^^^^^^^^^^^^^^^^^^^^^^^^^^^^^^^^^^^^^^^^^^^^^^^^^^^
  File "/home/airflow/.local/lib/python3.11/site-packages/airflow/operators/python.py", line 199, in execute
    return_value = self.execute_callable()
                   ^^^^^^^^^^^^^^^^^^^^^^^
  File "/home/airflow/.local/lib/python3.11/site-packages/airflow/operators/python.py", line 216, in execute_callable
    return self.python_callable(*self.op_args, **self.op_kwargs)
           ^^^^^^^^^^^^^^^^^^^^^^^^^^^^^^^^^^^^^^^^^^^^^^^^^^^^^
  File "/opt/airflow/scripts/kafka_consumer.py", line 59, in run_kafka_consumer
    raise ValueError(f"Missing 'data' key in Kafka payload: {payload}")
ValueError: Missing 'data' key in Kafka payload: {'error': {'code': 'invalid_access_key', 'message': 'You have not supplied a valid API Access Key.'}}
[2025-09-10T08:53:49.497+0000] {taskinstance.py:1138} INFO - Marking task as FAILED. dag_id=aviationstack_kafka_dag, task_id=run_kafka_consumer, execution_date=20250910T085338, start_date=20250910T085346, end_date=20250910T085349
[2025-09-10T08:53:49.505+0000] {standard_task_runner.py:107} ERROR - Failed to execute job 36 for task run_kafka_consumer (Missing 'data' key in Kafka payload: {'error': {'code': 'invalid_access_key', 'message': 'You have not supplied a valid API Access Key.'}}; 194)
[2025-09-10T08:53:49.531+0000] {local_task_job_runner.py:234} INFO - Task exited with return code 1
[2025-09-10T08:53:49.542+0000] {taskinstance.py:3280} INFO - 0 downstream tasks scheduled from follow-on schedule check
